Workbook
Name _3_Port_Valve: #REF!
Name _3_Port_Valve: #REF!
Name _4_Port_Valve: #REF!
Name _4_Port_Valve: #REF!
Name _MAS1: #REF!
Name _MAS1: #REF!
Name _MAS2: #REF!
Name EqList: #REF!
Name Foglio_di_calcolo: #REF!
Name Foglio_di_calcolo: #REF!
Name Foglio_di_calcolo: #REF!
Name Foglio_di_calcolo: #REF!
Name Foglio_di_calcolo: #REF!
Name Foglio_specifica: #REF!
Name Foglio_specifica: #REF!
Name Foglio_specifica: #REF!
Name Foglio_specifica: #REF!
Name Foglio_specifica: #REF!
Name KV_VALUE: #REF!
Name Picture: #REF!
Name Print_Area: 'COVER FCH'!$A$1:$J$48
Name Print_Area: 'COVER RHD'!$A$1:$J$48
Name Print_Area_MI: #REF!
Name w: #REF!
Name w: #REF!
Name w: #REF!
Name w: #REF!
Name w: #REF!

Sheet COVER RHD
A24: Committente | F24: Titolo Progetto
A25: AENOVA SRL Stabilimento di Borgo San Michele (LT) | F25: SITE DEVELOPMENT ADVANCED BASIC DESIGN
A29: Titolo Documento | F29: Codice Commessa
A30: HVAC DESIGN CRITERIA COLD CHAIN | F30: P5323
F32: Codice Documento
F33: P5323RHD002A
A35: Tabella Revisioni
A36: Revisione | B36: Descrizione: | C36: Emesso per RdO | J36: N° pagine:
A37: A | B37: Stesura: | C37: Ingegno | F37: Data: | G37: 45590 | H37: Firma: | I37: ING | J37: 3
B38: Controllo: | C38: Ingegno | F38: Data: | G38: 45590 | H38: Firma: | I38: ING
B39: Approvazione: | C39: L. Galligani | F39: Data: | G39: 45590 | H39: Firma: | I39: LGA
A40: Revisione | B40: Descrizione: | J40: N° pagine:
A41: B | B41: Stesura: | F41: Data: | H41: Firma:
B42: Controllo: | F42: Data: | H42: Firma:
B43: Approvazione: | F43: Data: | H43: Firma:
A48: Questo documento è proprietà della TECHNICONSULT FIRENZE S.r.l. che tutelerà i suoi diritti a termine di legge - This document is the sole property of TECHNICONSULT FIRENZE S.r.l. who will safeguard its rights according to the previsions of law
I85: Diffusore a ugello | J85: Canale | K85: Griglia di ripresa | L85: Canale
I86: Diffusore a ugello | J86: Canale | K86: Griglia di ripresa | L86: Canale

Sheet Design Criteria
A1: HVAC Design Criteria | AC1: EST | AD1: INV
AC2: =_xlfn.CEILING.MATH('Carichi t. LINK(NO PLOT)'!AA4,0.5) -> 4.5 | AD2: =_xlfn.CEILING.MATH('Carichi t. LINK(NO PLOT)'!AC8,0.5) -> 10.5 | AE2: LINK
A3: Sistema | C3: Locale | E3: Classe locale | G3: Livello Biologico | H3: Ricambi aria (Vol / amb / h) | J3: Area | K3: Altezza | L3: Volume | M3: Condizioni Interne Estate | Q3: Condizioni Interne Inverno | U3: Carichi interni | AC3: =_xlfn.CEILING.MATH('Carichi t. LBW(NO PLOT)'!AA5,0.5) -> 3 | AD3: =_xlfn.CEILING.MATH('Carichi t. LBW(NO PLOT)'!AC16,0.5) -> 6.5 | AE3: LBW MOVIM
U4: Illumin. | V4: Apparec. | W4: Persone | Z4: Rientrate di calore Estate | AA4: Totale Sensibile Estate | AB4: Dispersioni di calore Inverno | AC4: =_xlfn.CEILING.MATH('Carichi t. LBW(NO PLOT)'!AA4,0.5) -> 1 | AD4: =_xlfn.CEILING.MATH('Carichi t. LBW(NO PLOT)'!AC15,0.5) -> 6 | AE4: LBW CORR P0
M5: T | N5: tol. | O5: U.R. | P5: tol. | Q5: T | R5: tol. | S5: U.R. | T5: tol. | W5: n° | X5: Sensibile | Y5: Latente
J6: m2 | K6: m | L6: m3 | M6: °C | O6: % | Q6: °C | S6: % | U6: W/m2 | X6: W/p | Y6: W/p
A7: Codice | B7: Area servita | C7: Codice | D7: Descrizione | E7: Cliente | F7: GMP | H7: Standard | I7: Applicato | U7: 20 | V7: W | X7: 100 | Y7: 75 | Z7: W | AA7: W | AB7: W | AC7: =_xlfn.CEILING.MATH('Carichi t. LBW(NO PLOT)'!AA6,0.5) -> 11.5 | AD7: =_xlfn.CEILING.MATH('Carichi t. LBW(NO PLOT)'!AC17,0.5) -> 16.5 | AE7: LBW FUMO-A/L
A8: AH-102-01 | B8: LINK CORRIDOR P0 | C8: E001 | D8: MATERIAL RECEIVING LINK CORRIDOR | F8: NC | G8: N.A. | H8: 6 | I8: 6 | J8: 238.5 | K8: 2.7 | L8: =J8*K8 -> 643.95 | M8: 22 | N8: ≤ 25,0 | O8: ≤ 65,0 | P8: NA | Q8: 22 | R8: ≥ 15,0 | S8: ≤ 65,0 | T8: NA | U8: =J8*$U$7 -> 4770 | V8: ='CarichiApparecchiature(NO PLOT)'!J4 -> 1800 | W8: 0 | X8: =W8*$X$7 -> 0 | Y8: =W8*$Y$7 -> 0 | Z8: =L8*$AC$2 -> 2897.775 | AA8: =U8+V8+X8+Z8 -> 9467.775 | AB8: =L8*$AD$2 -> 6761.475 | AC8: =_xlfn.CEILING.MATH('Carichi t. LBW(NO PLOT)'!AA7,0.5) -> 13.5 | AD8: =_xlfn.CEILING.MATH('Carichi t. LBW(NO PLOT)'!AC18,0.5) -> 14 | AE8: LBW CORR P1
AC9: =_xlfn.CEILING.MATH('Carichi t. LBW(NO PLOT)'!AA8,0.5) -> 8.5 | AD9: =_xlfn.CEILING.MATH('Carichi t. LBW(NO PLOT)'!AC19,0.5) -> 12.5 | AE9: LBW WC P1
A10: AH-103-01 | B10: MAGAZZINO BASSO P0 | C10: A001 | D10: ENTRANCE | F10: NC | G10: N.A. | H10: 3 | I10: 3 | J10: 18.51 | K10: 5.2 | L10: =J10*K10 -> 96.252 | M10: 22 | N10: ±2 | O10: ≤ 65,0 | P10: NA | Q10: 22 | R10: ±2 | S10: ≤ 65,0 | T10: NA | U10: =J10*$U$7 -> 370.2 | V10: ='CarichiApparecchiature(NO PLOT)'!J7 -> 0 | W10: 0 | X10: =W10*$X$7 -> 0 | Y10: =W10*$Y$7 -> 0 | Z10: =L10*$AC$4 -> 96.252 | AA10: =U10+V10+X10+Z10 -> 466.452 | AB10: =L10*$AD$4 -> 577.512 | AC10: =_xlfn.CEILING.MATH('Carichi t. LBW(NO PLOT)'!AA11,0.5) -> 4 | AD10: =_xlfn.CEILING.MATH('Carichi t. LBW(NO PLOT)'!AC22,0.5) -> 5.5 | AE10: LBW AREA TEC
A11: AH-103-01 | B11: MAGAZZINO BASSO P0 | C11: A002 | D11: HANDLING AREA | F11: NC | G11: N.A. | H11: 3 | I11: 3 | J11: 366.14 | K11: 5.2 | L11: =J11*K11 -> 1903.928 | M11: 22 | N11: ≤ 25,0 | O11: ≤ 65,0 | P11: NA | Q11: 22 | R11: ≥ 15,0 | S11: ≤ 65,0 | T11: NA | U11: =J11*$U$7 -> 7322.8 | V11: ='CarichiApparecchiature(NO PLOT)'!J8 -> 1462.5 | W11: 10 | X11: =W11*$X$7 -> 1000 | Y11: =W11*$Y$7 -> 750 | Z11: =L11*$AC$3 -> 5711.784 | AA11: =U11+V11+X11+Z11 -> 15497.084 | AB11: =L11*$AD$3 -> 12375.532
A12: AH-103-01 | B12: MAGAZZINO BASSO P1 | C12: A101 | D12: FILTER AGAINST FIRE | F12: NC | G12: N.A. | H12: 6 | I12: 6 | J12: 8.9 | K12: 2.7 | L12: =J12*K12 -> 24.03 | M12: 22 | N12: ±2 | O12: ≤ 65,0 | P12: NA | Q12: 22 | R12: ±2 | S12: ≤ 65,0 | T12: NA | U12: =J12*$U$7 -> 178 | V12: ='CarichiApparecchiature(NO PLOT)'!J11 -> 0 | W12: 0 | X12: =W12*$X$7 -> 0 | Y12: =W12*$Y$7 -> 0 | Z12: =L12*$AC$7 -> 276.345 | AA12: =U12+V12+X12+Z12 -> 454.345 | AB12: =L12*$AD$7 -> 396.495 | AC12: =_xlfn.CEILING.MATH('Carichi t. LBW(NO PLOT)'!AA9,0.5) -> 8.5 | AD12: =_xlfn.CEILING.MATH('Carichi t. LBW(NO PLOT)'!AC20,0.5) -> 12.5 | AE12: LBW SPOGL P1
A13: AH-103-01 | B13: MAGAZZINO BASSO P1 | C13: A102 | D13: AIRLOCK VT | F13: NC | G13: N.A. | H13: 6 | I13: 6 | J13: 5.9 | K13: 2.7 | L13: =J13*K13 -> 15.93 | M13: 22 | N13: ±2 | O13: ≤ 65,0 | P13: NA | Q13: 22 | R13: ±2 | S13: ≤ 65,0 | T13: NA | U13: =J13*$U$7 -> 118 | V13: ='CarichiApparecchiature(NO PLOT)'!J12 -> 0 | W13: 0 | X13: =W13*$X$7 -> 0 | Y13: =W13*$Y$7 -> 0 | Z13: =L13*$AC$7 -> 183.195 | AA13: =U13+V13+X13+Z13 -> 301.195 | AB13: =L13*$AD$7 -> 262.845 | AC13: =_xlfn.CEILING.MATH('Carichi t. REV(NO PLOT)'!AA4,0.5) -> 22 | AD13: =_xlfn.CEILING.MATH('Carichi t. REV(NO PLOT)'!AA11,0.5) -> 11 | AE13: REV P0-1
A14: AH-103-01 | B14: MAGAZZINO BASSO P1 | C14: A103 | D14: CORRIDOR | F14: NC | G14: N.A. | H14: 6 | I14: 6 | J14: 23.36 | K14: 2.7 | L14: =J14*K14 -> 63.072 | M14: 22 | N14: ±2 | O14: ≤ 65,0 | P14: NA | Q14: 22 | R14: ±2 | S14: ≤ 65,0 | T14: NA | U14: =J14*$U$7 -> 467.2 | V14: ='CarichiApparecchiature(NO PLOT)'!J13 -> 0 | W14: 0 | X14: =W14*$X$7 -> 0 | Y14: =W14*$Y$7 -> 0 | Z14: =L14*$AC$8 -> 851.472 | AA14: =U14+V14+X14+Z14 -> 1318.672 | AB14: =L14*$AD$8 -> 883.008 | AC14: =AC7/2 -> 5.75 | AD14: =AD7/2 -> 8.25 | AE14: REV P0-2
A15: AH-103-1 + FC-103-01 (2) | B15: REVAMPING P0 | C15: 0428 | D15: PREDISPOSITION TO DS | F15: NC | G15: N.A. | H15: 3 | I15: 3 | J15: 63.81 | K15: 2.7 | L15: =J15*K15 -> 172.287 | M15: 22 | N15: ≤ 25,0 | O15: ≤ 65,0 | P15: NA | Q15: 22 | R15: ≥ 15,0 | S15: ≤ 65,0 | T15: NA | U15: =J15*$U$7 -> 1276.2 | V15: ='CarichiApparecchiature(NO PLOT)'!J23 -> 10800 | W15: 0 | X15: =W15*$X$7 -> 0 | Y15: =W15*$Y$7 -> 0 | Z15: =L15*AC13 -> 3790.314 | AA15: =U15+V15+X15+Z15 -> 15866.514 | AB15: =L15*AD13 -> 1895.157
A16: AH-103-1 (4) | B16: REVAMPING P0 - PREDISPOSIZIONE | C16: 0437 | D16: REVAMPING SAMPLING ON LINE (FUTURO) | F16: NC | G16: N.A. | H16: 3 | I16: 3 | J16: 43.5 | K16: 3 | L16: =J16*K16 -> 130.5 | M16: NA | N16: NA | O16: NA | P16: NA | Q16: NA | R16: NA | S16: NA | T16: NA | U16: NA | V16: NA | W16: 0 | X16: NA | Y16: NA | Z16: NA | AA16: NA | AB16: NA | AC16: 7.5 | AD16: =_xlfn.CEILING.MATH('Carichi t. LBW(NO PLOT)'!AC27,0.5) -> 0 | AE16: LBW WC P1
A17: AH-103-1 (4) | B17: REVAMPING P1 - PREDISPOSIZIONE | C17: 1278 | D17: REVAMPING PASSAGEWAY (FUTURO) | F17: NC | G17: N.A. | H17: 3 | I17: 3 | J17: 52.56 | K17: 3 | L17: =J17*K17 -> 157.68 | M17: NA | N17: NA | O17: NA | P17: NA | Q17: NA | R17: NA | S17: NA | T17: NA | U17: NA | V17: NA | W17: 0 | X17: NA | Y17: NA | Z17: NA | AA17: NA | AB17: NA | AC17: =_xlfn.CEILING.MATH('Carichi t. LBW(NO PLOT)'!AA31,0.5) -> 0 | AD17: =_xlfn.CEILING.MATH('Carichi t. LBW(NO PLOT)'!AC44,0.5) -> 0 | AE17: LBW WC P1
A18: AH-103-1 (4) | B18: REVAMPING P1 - PREDISPOSIZIONE | C18: 1373 | D18: REVAMPING CALIBRATION AREA (FUTURO) | F18: NC | G18: N.A. | H18: 3 | I18: 3 | J18: 70.27 | K18: 3 | L18: =J18*K18 -> 210.81 | M18: NA | N18: NA | O18: NA | P18: NA | Q18: NA | R18: NA | S18: NA | T18: NA | U18: NA | V18: NA | W18: 0 | X18: NA | Y18: NA | Z18: NA | AA18: NA | AB18: NA | AC18: =_xlfn.CEILING.MATH('Carichi t. LBW(NO PLOT)'!AA34,0.5) -> 0 | AD18: =_xlfn.CEILING.MATH('Carichi t. LBW(NO PLOT)'!AC47,0.5) -> 0 | AE18: LBW AREA TEC
A20: AH-104-1 + FC-104-01 (2) | B20: MAGAZZINO BASSO P1 | C20: A104 | D20: MALE CHANGING ROOM | F20: NC | G20: N.A. | H20: (1) | I20: (1) (2) | J20: 18.37 | K20: 2.7 | L20: =J20*K20 -> 49.599 | M20: 22 | N20: ±2 | O20: ≤ 65,0 | P20: NA | Q20: 22 | R20: ±2 | S20: ≤ 65,0 | T20: NA | U20: =J20*$U$7 -> 367.4 | V20: ='CarichiApparecchiature(NO PLOT)'!J14 -> 0 | W20: =_xlfn.CEILING.MATH(25*0.25,1) -> 7 | X20: =W20*$X$7 -> 700 | Y20: =W20*$Y$7 -> 525 | Z20: =L20*$AC$12 -> 421.5915 | AA20: =U20+V20+X20+Z20 -> 1488.9915 | AB20: =L20*$AD$12 -> 619.9875 | AC20: =_xlfn.CEILING.MATH('Carichi t. LINK(NO PLOT)'!AA4,0.5) -> 4.5 | AD20: =_xlfn.CEILING.MATH('Carichi t. LINK(NO PLOT)'!AA8,0.5) -> 7.5 | AE20: LOG OUT
A21: AH-104-1 + FC-104-01 (2) | B21: MAGAZZINO BASSO P1 | C21: A105 | D21: MALE WC | F21: NC | G21: N.A. | H21: 0 | I21: 0 (2) | J21: 23 | K21: 2.7 | L21: =J21*K21 -> 62.1 | M21: 22 | N21: ±2 | O21: ≤ 65,0 | P21: NA | Q21: 22 | R21: ±2 | S21: ≤ 65,0 | T21: NA | U21: =J21*$U$7 -> 460 | V21: ='CarichiApparecchiature(NO PLOT)'!J15 -> 0 | W21: 0 | X21: =W21*$X$7 -> 0 | Y21: =W21*$Y$7 -> 0 | Z21: =L21*$AC$9/3 -> 175.95 | AA21: =U21+V21+X21+Z21 -> 635.95 | AB21: =L21*$AD$9 -> 776.25
A22: AH-104-1 + FC-104-01 (2) | B22: MAGAZZINO BASSO P1 | C22: A106 | D22: FEMALE WC | F22: NC | G22: N.A. | H22: 0 | I22: 0 (2) | J22: 23 | K22: 2.7 | L22: =J22*K22 -> 62.1 | M22: 22 | N22: ±2 | O22: ≤ 65,0 | P22: NA | Q22: 22 | R22: ±2 | S22: ≤ 65,0 | T22: NA | U22: =J22*$U$7 -> 460 | V22: ='CarichiApparecchiature(NO PLOT)'!J16 -> 0 | W22: 0 | X22: =W22*$X$7 -> 0 | Y22: =W22*$Y$7 -> 0 | Z22: =L22*$AC$9/3 -> 175.95 | AA22: =U22+V22+X22+Z22 -> 635.95 | AB22: =L22*$AD$9 -> 776.25 | AC22: 0 | AD22: 0 | AE22: interni
A23: AH-104-1 + FC-104-01 (2) | B23: MAGAZZINO BASSO P1 | C23: A107 | D23: FEMALE CHANGING ROOM | F23: NC | G23: N.A. | H23: (1) | I23: (1) (2) | J23: 26 | K23: 2.7 | L23: =J23*K23 -> 70.2 | M23: 22 | N23: ±2 | O23: ≤ 65,0 | P23: NA | Q23: 22 | R23: ±2 | S23: ≤ 65,0 | T23: NA | U23: =J23*$U$7 -> 520 | V23: ='CarichiApparecchiature(NO PLOT)'!J17 -> 0 | W23: =_xlfn.CEILING.MATH(39*0.25,1) -> 10 | X23: =W23*$X$7 -> 1000 | Y23: =W23*$Y$7 -> 750 | Z23: =L23*$AC$12 -> 596.7 | AA23: =U23+V23+X23+Z23 -> 2116.7 | AB23: =L23*$AD$12 -> 877.5 | AC23: 13 | AD23: 11 | AE23: esposti
A24: AH-104-1 + FC-104-01 (2) | B24: MAGAZZINO BASSO P1 | C24: A110 | D24: SUPERVISOR ROOM | F24: NC | G24: N.A. | H24: (1) | I24: (1) (2) | J24: 7 | K24: 2.7 | L24: =J24*K24 -> 18.9 | M24: 22 | N24: ±2 | O24: ≤ 65,0 | P24: NA | Q24: 22 | R24: ±2 | S24: ≤ 65,0 | T24: NA | U24: =J24*$U$7 -> 140 | V24: ='CarichiApparecchiature(NO PLOT)'!J18 -> 75 | W24: 1 | X24: =W24*$X$7 -> 100 | Y24: =W24*$Y$7 -> 75 | Z24: =L24*$AC$7 -> 217.35 | AA24: =U24+V24+X24+Z24 -> 532.35 | AB24: =L24*$AD$7 -> 311.85
A25: AH-104-1 + FC-104-01 (2) | B25: MAGAZZINO BASSO P1 | C25: A109 | D25: UPS ROOM | F25: NC | G25: N.A. | H25: 3 | I25: 3 | J25: 6 | K25: 2.7 | L25: =J25*K25 -> 16.2 | M25: 25 | N25: ≤ 30,0 | O25: NA | P25: NA | Q25: 20 | R25: ≥ 15,0 | S25: NA | T25: NA | U25: =J25*$U$7 -> 120 | V25: ='CarichiApparecchiature(NO PLOT)'!J19 -> 5500 | W25: 0 | X25: =W25*$X$7 -> 0 | Y25: =W25*$Y$7 -> 0 | Z25: =L25*$AC$7 -> 186.3 | AA25: =U25+V25+X25+Z25 -> 5806.3 | AB25: =L25*$AD$7 -> 267.3
AC26: =_xlfn.CEILING.MATH('Carichi t. REV(NO PLOT)'!AA6,1) -> 7 | AD26: =_xlfn.CEILING.MATH('Carichi t. REV(NO PLOT)'!AA13,0.5) -> 4 | AE26: CORRID NO BETA
A27: AH-105-01 | B27: REVAMPING P0 | C27: E002 | D27: LOGISTIC AIRLOCK OUT | F27: NC | G27: N.A. | H27: 6 | I27: 6 | J27: 24.5 | K27: 2.7 | L27: =J27*K27 -> 66.15 | M27: 22 | N27: ±2 | O27: ≤ 65,0 | P27: NA | Q27: 22 | R27: ±2 | S27: ≤ 65,0 | T27: NA | U27: =J27*$U$7 -> 490 | V27: ='CarichiApparecchiature(NO PLOT)'!J30 -> 0 | W27: 0 | X27: =W27*$X$7 -> 0 | Y27: =W27*$Y$7 -> 0 | Z27: =L27*$AC$20 -> 297.675 | AA27: =U27+V27+X27+Z27 -> 787.675 | AB27: =L27*$AD$20 -> 496.125
A28: AH-105-01 | B28: REVAMPING P0 | C28: E003 | D28: LOGISTIC AIRLOCK IN | F28: NC | G28: N.A. | H28: 6 | I28: 6 | J28: 4.58 | K28: 2.4 | L28: =J28*K28 -> 10.992 | M28: 22 | N28: ±2 | O28: ≤ 65,0 | P28: NA | Q28: 22 | R28: ±2 | S28: ≤ 65,0 | T28: NA | U28: =J28*$U$7 -> 91.6 | V28: ='CarichiApparecchiature(NO PLOT)'!J29 -> 0 | W28: 0 | X28: =W28*$X$7 -> 0 | Y28: =W28*$Y$7 -> 0 | Z28: =L28*$AC$22 -> 0 | AA28: =U28+V28+X28+Z28 -> 91.6 | AB28: =L28*$AD$22 -> 0
A30: AH-106-1 | B30: REVAMPING P0 | C30: 0605/0311 | D30: WAREHOUSE NORTH SIDE / CORRIDOR | F30: NC | G30: N.A. | H30: 3 | I30: 3 | J30: 682 | K30: 3 | L30: =J30*K30 -> 2046 | M30: 22 | N30: ≤ 25,0 | O30: ≤ 65,0 | P30: NA | Q30: 22 | R30: ≥ 15,0 | S30: ≤ 65,0 | T30: NA | U30: =J30*$U$7 -> 13640 | V30: ='CarichiApparecchiature(NO PLOT)'!J32 -> 2520 | W30: 1 | X30: =W30*$X$7 -> 100 | Y30: =W30*$Y$7 -> 75 | Z30: =L30*$AC$22 -> 0 | AA30: =U30+V30+X30+Z30 -> 16260 | AB30: =L30*$AD$22 -> 0
A31: AH-106-1 | B31: REVAMPING P0 | C31: 0606 | D31: NO BETA AREA CORRIDOR | F31: NC | G31: N.A. | H31: 3 | I31: 3 | J31: 228 | K31: =AVERAGE((3.9-0.4),AVERAGE((3.9-0.4),(3.4-0.4))) -> 3.375 | L31: =J31*K31 -> 769.5 | M31: 22 | N31: ≤ 25,0 | O31: ≤ 65,0 | P31: NA | Q31: 22 | R31: ≥ 15,0 | S31: ≤ 65,0 | T31: NA | U31: =J31*$U$7 -> 4560 | V31: ='CarichiApparecchiature(NO PLOT)'!J33 -> 0 | W31: 0 | X31: =W31*$X$7 -> 0 | Y31: =W31*$Y$7 -> 0 | Z31: =L31*$AC$26 -> 5386.5 | AA31: =U31+V31+X31+Z31 -> 9946.5 | AB31: =L31*$AD$26 -> 3078
A32: AH-106-1 | B32: REVAMPING P0 | C32: 0615 | D32: WASTE MATERIAL EXIT | F32: NC | G32: N.A. | H32: 3 | I32: 3 | J32: 24.3 | K32: 3.6 | L32: =J32*K32 -> 87.48 | M32: 22 | N32: ≤ 25,0 | O32: ≤ 65,0 | P32: NA | Q32: 22 | R32: ≥ 15,0 | S32: ≤ 65,0 | T32: NA | U32: =J32*$U$7 -> 486 | V32: ='CarichiApparecchiature(NO PLOT)'!J34 -> 0 | W32: 0 | X32: =W32*$X$7 -> 0 | Y32: =W32*$Y$7 -> 0 | Z32: =L32*$AC$14 -> 503.01 | AA32: =U32+V32+X32+Z32 -> 989.01 | AB32: =L32*$AD$14 -> 721.71
A34: AH-107-1 + FC-107-01 (2) | B34: REVAMPING P0 | C34: B001 | D34: DS STORAGE | F34: NC | G34: N.A. | H34: 3 | I34: 3 | J34: 37.18 | K34: 2.7 | L34: =J34*K34 -> 100.386 | M34: 22 | N34: ≤ 25,0 | O34: ≤ 65,0 | P34: NA | Q34: 22 | R34: ≥ 15,0 | S34: ≤ 65,0 | T34: NA | U34: =J34*$U$7 -> 743.6 | V34: ='CarichiApparecchiature(NO PLOT)'!J25 -> 4500 | W34: 0 | X34: =W34*$X$7 -> 0 | Y34: =W34*$Y$7 -> 0 | Z34: =L34*$AC$14 -> 577.2195 | AA34: =U34+V34+X34+Z34 -> 5820.8195 | AB34: =L34*$AD$14 -> 828.1845
A35: AH-107-1 + FC-107-01 (2) | B35: REVAMPING P0 | C35: B002 | D35: CHECK ROOM/AIRLOCK | F35: NC | G35: N.A. | H35: 3 | I35: 3 | J35: 18 | K35: 2.7 | L35: =J35*K35 -> 48.6 | M35: 22 | N35: ≤ 25,0 | O35: ≤ 65,0 | P35: NA | Q35: 22 | R35: ≥ 15,0 | S35: ≤ 65,0 | T35: NA | U35: =J35*$U$7 -> 360 | V35: ='CarichiApparecchiature(NO PLOT)'!J26 -> 900 | W35: 1 | X35: =W35*$X$7 -> 100 | Y35: =W35*$Y$7 -> 75 | Z35: =L35*$AC$22 -> 0 | AA35: =U35+V35+X35+Z35 -> 1360 | AB35: =L35*$AD$22 -> 0
A36: AH-107-1 + FC-107-01 (2) | B36: REVAMPING P0 | C36: B003 | D36: RECEIVING | F36: NC | G36: N.A. | H36: 3 | I36: 3 | J36: 13 | K36: 2.7 | L36: =J36*K36 -> 35.1 | M36: 22 | N36: ≤ 25,0 | O36: ≤ 65,0 | P36: NA | Q36: 22 | R36: ≥ 15,0 | S36: ≤ 65,0 | T36: NA | U36: =J36*$U$7 -> 260 | V36: ='CarichiApparecchiature(NO PLOT)'!J27 -> 0 | W36: 0 | X36: =W36*$X$7 -> 0 | Y36: =W36*$Y$7 -> 0 | Z36: =L36*$AC$14 -> 201.825 | AA36: =U36+V36+X36+Z36 -> 461.825 | AB36: =L36*$AD$14 -> 289.575
A38: FC-102-01 (3) | B38: LINK CORRIDOR P1 | C38: E102 | D38: ELECTRIC ROOM | F38: NC | G38: N.A. | H38: 0 | I38: 0 (3) | J38: 27 | K38: 2.7 | L38: =J38*K38 -> 72.9 | M38: 22 | N38: ±2 | O38: ≤ 65,0 | P38: NA | Q38: 22 | R38: ±2 | S38: ≤ 65,0 | T38: NA | U38: =J38*$U$7 -> 540 | V38: ='CarichiApparecchiature(NO PLOT)'!J21 -> 6100 | W38: 0 | X38: =W38*$X$7 -> 0 | Y38: =W38*$Y$7 -> 0 | Z38: =L38*$AC$7 -> 838.35 | AA38: =U38+V38+X38+Z38 -> 7478.35 | AB38: =L38*$AD$7 -> 1202.85
A40: Note | C40: (1) Rinnovi aria esterna ≥ 39,6 mc/h pp (2) Ventilconvettori + aria primaria (3) Ventilconvettori (4) Aria primaria | E40: NC Non Classificato NA Non Applicabile
M42: Condizioni Esterne Estate | Q42: Condizioni Esterne Inverno
B44: Cella con riferimento ad altra cella o foglio | M44: T | N44: tol. | O44: U.R. | P44: tol. | Q44: T | R44: tol. | S44: U.R. | T44: tol.
M45: °C | O45: % | Q45: °C | S45: %
B46: Cella contenente formula | M46: 36 | N46: - | O46: 60 | P46: - | Q46: -5 | R46: - | S46: 80 | T46: -
B48: Cella compilata e controllata
...

Sheet CarichiApparecchiature(NO PLOT)
A1: Carichi Termici Equipment
A2: Locale | B2: Descrizione | C2: Apparecchiatura | D2: Carico elettrico | E2: N. | F2: % utilizzo | G2: % diss. | H2: Carico dissipato unit | I2: Totale Carico dissipato | J2: Totale locale
D3: W | H3: W | I3: W | J3: W
A4: ='Design Criteria'!C8 -> E001 | B4: ='Design Criteria'!D8 -> MATERIAL RECEIVING LINK CORRIDOR | C4: Ricarica AGV | D4: 3000 | E4: 0 | F4: 0.5 | G4: 0.15 | H4: =G4*E4*F4*D4 -> 0 | I4: =H4*E4 -> 0 | J4: =SUM(I4:I5) -> 1800
C5: Motori rulliere | D5: 1000 | E5: 4 | F5: 0.75 | G5: 0.15 | H5: =G5*E5*F5*D5 -> 450 | I5: =H5*E5 -> 1800
A7: ='Design Criteria'!C10 -> A001 | B7: ='Design Criteria'!D10 -> ENTRANCE | H7: =G7*F7*D7 -> 0 | I7: =H7*E7 -> 0 | J7: =SUM(I7:I7) -> 0
A8: ='Design Criteria'!C11 -> A002 | B8: ='Design Criteria'!D11 -> HANDLING AREA | C8: Motori rulliere | D8: 1000 | E8: 3 | F8: 0.75 | G8: 0.15 | H8: =G8*E8*F8*D8 -> 337.5 | I8: =H8*E8 -> 1012.5 | J8: =SUM(I8:I10) -> 1462.5
C9: Wrapping machine | D9: 2000 | E9: 1 | F9: 0.5 | G9: 0.15 | H9: =G9*F9*D9 -> 150 | I9: =H9*E9 -> 150
C10: Cambio pallet | D10: 4000 | E10: 1 | F10: 0.5 | G10: 0.15 | H10: =G10*F10*D10 -> 300 | I10: =H10*E10 -> 300
A11: ='Design Criteria'!C12 -> A101 | B11: ='Design Criteria'!D12 -> FILTER AGAINST FIRE | J11: =SUM(I11:I11) -> 0
A12: ='Design Criteria'!C13 -> A102 | B12: ='Design Criteria'!D13 -> AIRLOCK VT | H12: =G12*F12*D12 -> 0 | I12: =H12*E12 -> 0 | J12: =SUM(I12:I12) -> 0
A13: ='Design Criteria'!C14 -> A103 | B13: ='Design Criteria'!D14 -> CORRIDOR | J13: =SUM(I13:I13) -> 0
A14: ='Design Criteria'!C20 -> A104 | B14: ='Design Criteria'!D20 -> MALE CHANGING ROOM | H14: =G14*F14*D14 -> 0 | I14: =H14*E14 -> 0 | J14: =SUM(I14:I14) -> 0
A15: ='Design Criteria'!C21 -> A105 | B15: ='Design Criteria'!D21 -> MALE WC | H15: =G15*F15*D15 -> 0 | I15: =H15*E15 -> 0 | J15: =SUM(I15:I15) -> 0
A16: ='Design Criteria'!C22 -> A106 | B16: ='Design Criteria'!D22 -> FEMALE WC | H16: =G16*F16*D16 -> 0 | I16: =H16*E16 -> 0 | J16: =SUM(I16:I16) -> 0
A17: ='Design Criteria'!C23 -> A107 | B17: ='Design Criteria'!D23 -> FEMALE CHANGING ROOM | J17: =SUM(I17:I17) -> 0
A18: ='Design Criteria'!C24 -> A110 | B18: ='Design Criteria'!D24 -> SUPERVISOR ROOM | C18: PC | D18: 500 | E18: 1 | F18: 1 | G18: 0.15 | H18: =G18*F18*D18 -> 75 | I18: =H18*E18 -> 75 | J18: =SUM(I18) -> 75
A19: ='Design Criteria'!C25 -> A109 | B19: ='Design Criteria'!D25 -> UPS ROOM | C19: UPS | H19: =G19*F19*D19 -> 0 | I19: =(5.5)*1000 -> 5500 | J19: =SUM(I19:I19) -> 5500
A21: ='Design Criteria'!C38 -> E102 | B21: ='Design Criteria'!D38 -> ELECTRIC ROOM | F21: 1 | G21: 0.15 | H21: =G21*F21*D21 -> 0 | I21: =(4.1+2)*1000 -> 6100 | J21: =SUM(I21:I21) -> 6100
A23: ='Design Criteria'!C15 -> 0428 | B23: ='Design Criteria'!D15 -> PREDISPOSITION TO DS | C23: Freezer -80 °C | D23: 1000 | E23: 12 | F23: 1 | G23: 0.9 | H23: =G23*F23*D23 -> 900 | I23: =H23*E23 -> 10800 | J23: =SUM(I23) -> 10800
A25: ='Design Criteria'!C34 -> B001 | B25: ='Design Criteria'!D34 -> DS STORAGE | C25: Freezer -80 °C | D25: 1000 | E25: 5 | F25: 1 | G25: 0.9 | H25: =G25*F25*D25 -> 900 | I25: =H25*E25 -> 4500 | J25: =SUM(I25) -> 4500
A26: ='Design Criteria'!C35 -> B002 | B26: ='Design Criteria'!D35 -> CHECK ROOM/AIRLOCK | C26: Freezer -80 °C | D26: 1000 | E26: 1 | F26: 1 | G26: 0.9 | H26: =G26*F26*D26 -> 900 | I26: =H26*E26 -> 900 | J26: =SUM(I26) -> 900
A27: ='Design Criteria'!C36 -> B003 | B27: ='Design Criteria'!D36 -> RECEIVING | H27: =G27*F27*D27 -> 0 | I27: =H27*E27 -> 0 | J27: =SUM(I27:I27) -> 0
A29: ='Design Criteria'!C28 -> E003 | B29: ='Design Criteria'!D28 -> LOGISTIC AIRLOCK IN | H29: =G29*F29*D29 -> 0 | I29: =H29*E29 -> 0 | J29: =SUM(I29:I29) -> 0
A30: ='Design Criteria'!C27 -> E002 | B30: ='Design Criteria'!D27 -> LOGISTIC AIRLOCK OUT | H30: =G30*F30*D30 -> 0 | I30: =H30*E30 -> 0 | J30: =SUM(I30:I30) -> 0
A32: ='Design Criteria'!C30 -> 0605/0311 | B32: ='Design Criteria'!D30 -> WAREHOUSE NORTH SIDE / CORRIDOR | C32: Ricarica AGV | D32: 3000 | E32: 4 | F32: 0.35 | G32: 0.15 | H32: =G32*E32*F32*D32 -> 630 | I32: =H32*E32 -> 2520 | J32: =SUM(I32) -> 2520
A33: ='Design Criteria'!C31 -> 0606 | B33: ='Design Criteria'!D31 -> NO BETA AREA CORRIDOR | H33: =G33*F33*D33 -> 0 | I33: =H33*E33 -> 0 | J33: =SUM(I33:I33) -> 0
A34: ='Design Criteria'!C32 -> 0615 | B34: ='Design Criteria'!D32 -> WASTE MATERIAL EXIT | H34: =G34*F34*D34 -> 0 | I34: =H34*E34 -> 0 | J34: =SUM(I34:I34) -> 0
H37: TOTALE | J37: =SUM(J4:J36) -> 33657.5
G64: 44697
G65: 44697

Sheet Carichi t. REV(NO PLOT)
A1: Locale | C1: ESTATE
C2: Ti (°C) | D2: Pavimento contro terra | G2: Solaio interpiano con locali non condizionati | J2: Copertura | M2: Pareti Esterne | P2: Vetrate Esterne | S2: Pareti su locali non condizionati | V2: Contrib. irragg.copertura | W2: Irragg. sup vetrate | X2: Contrib. irragg.pareti | Y2: Fatt correttivo altezza | Z2: Q TOT (kW)
A3: Descrizione | B3: Codice | D3: T (°C) | E3: Superficie (m2) | F3: Q (W) | G3: T (°C) | H3: Superficie (m2) | I3: Q (W) | J3: T (°C) | K3: Superficie (m2) | L3: Q (W) | M3: T (°C) | N3: Superficie (m2) | O3: Q (W) | P3: T (°C) | Q3: Superficie (m2) | R3: Q (W) | S3: T (°C) | T3: Superficie (m2) | U3: Q (W) | V3: Q (W) | W3: Q (W) | X3: Q (W) | AA3: W/mc
A4: ='Design Criteria'!D15 -> PREDISPOSITION TO DS | B4: ='Design Criteria'!C15 -> 0428 | C4: ='Design Criteria'!M15 -> 22 | D4: 15 | E4: ='Design Criteria'!J15 -> 63.81 | F4: 0 | G4: 30 | H4: 0 | I4: =$E$24*H4*(-C4+G4) -> 0 | J4: ='Design Criteria'!$M$46 -> 36 | K4: 0 | L4: =$E$19*K4*(-C4+J4) -> 0 | M4: ='Design Criteria'!$M$46 -> 36 | N4: =(14+5)*3 -> 57 | O4: =$E$21*N4*(M4-C4) -> 286.31183 | P4: ='Design Criteria'!$M$46 -> 36 | Q4: =(12.5+3.5)*1 -> 16 | R4: =$E$23*Q4*(P4-C4) -> 560 | U4: 0 | V4: =MAX(SUM(P81)-L4,0) -> 0 | W4: =SUM(M66:M67) -> 2824.1347 | X4: =MAX(SUM(P82:P85)-O4,0) -> 46.391127 | Y4: 1 | Z4: =(F4+I4+O4+R4+U4+L4+V4+W4+X4)*Y4/1000 -> 3.7168377 | AA4: =(Z4)/'Design Criteria'!$L$15*1000 -> 21.573524
A6: ='Design Criteria'!D31 -> NO BETA AREA CORRIDOR | B6: ='Design Criteria'!C31 -> 0606 | C6: ='Design Criteria'!M31 -> 22 | D6: 15 | E6: ='Design Criteria'!J31 -> 228 | F6: 0 | G6: 30 | H6: 0 | I6: =$E$24*H6*(-C6+G6) -> 0 | J6: ='Design Criteria'!$M$46 -> 36 | K6: 0 | L6: =$E$19*K6*(-C6+J6) -> 0 | M6: ='Design Criteria'!$M$46 -> 36 | N6: =(20)*3.9 -> 78 | O6: =$E$22*N6*(M6-C6) -> 265.01611 | P6: ='Design Criteria'!$M$46 -> 36 | Q6: =(20)*1 -> 20 | R6: =$E$23*Q6*(P6-C6) -> 700 | U6: 0 | V6: =MAX(SUM(P89)-L6,0) -> 0 | W6: =SUM(M71) -> 4050.7535 | X6: =MAX(SUM(P90:P93)-O6,0) -> 283.49708 | Y6: 1 | Z6: =(F6+I6+O6+R6+U6+L6+V6+W6+X6)*Y6/1000 -> 5.2992667 | AA6: =(Z6)/'Design Criteria'!$L$31*1000 -> 6.8866364
A8: Locale | C8: INVERNO
C9: Ti (°C) | D9: Pavimento contro terra | G9: Solaio interpiano | J9: Copertura | M9: Pareti Esterne | P9: Vetrate Esterne | S9: Pareti su locali non condizionati | V9: Contrib. irragg.copertura | W9: Irragg. sup vetrate | X9: Contrib. irragg.pareti | Y9: Fatt correttivo altezza | Z9: Q TOT (kW)
A10: Descrizione | B10: Codice | D10: T (°C) | E10: Superficie (m2) | F10: Q (W) | G10: T (°C) | H10: Superficie (m2) | I10: Q (W) | J10: T (°C) | K10: Superficie (m2) | L10: Q (W) | M10: T (°C) | N10: Superficie (m2) | O10: Q (W) | P10: T (°C) | Q10: Superficie (m2) | R10: Q (W) | S10: T (°C) | T10: Superficie (m2) | U10: Q (W) | V10: Q (W) | W10: Q (W) | X10: Q (W) | AA10: W/mc
A11: =A4 -> PREDISPOSITION TO DS | B11: =B4 -> 0428 | C11: ='Design Criteria'!Q15 -> 22 | D11: 10 | E11: =E4 -> 63.81 | F11: =-$E$18*E11*(D11-C11) -> 215.60982 | G11: 10 | H11: =H4 -> 0 | I11: =$E$24*H11*(C11-G11) -> 0 | J11: ='Design Criteria'!$Q$46 -> -5 | K11: =K4 -> 0 | L11: =$E$19*K11*(C11-J11) -> 0 | M11: ='Design Criteria'!$Q$46 -> -5 | N11: =N4 -> 57 | O11: =-$E$21*N11*(M11-C11) -> 552.17281 | P11: ='Design Criteria'!$Q$46 -> -5 | Q11: =Q4 -> 16 | R11: =$E$23*Q11*(-P11+C11) -> 1080 | S11: =S4 -> 0 | T11: =T4 -> 0 | U11: =-$E$20*T11*(S11-C11) -> 0 | V11: 0 | W11: 0 | X11: 0 | Y11: =Y4 -> 1 | Z11: =(F11+I11+O11+R11+U11+L11+V11+W11+X11)*Y11/1000 -> 1.8477826 | AA11: =(Z11)/'Design Criteria'!$L$15*1000 -> 10.725026
A13: =A6 -> NO BETA AREA CORRIDOR | B13: =B6 -> 0606 | C13: ='Design Criteria'!Q31 -> 22 | D13: 10 | E13: =E6 -> 228 | F13: =-$E$18*E13*(D13-C13) -> 770.39711 | G13: 10 | H13: =H6 -> 0 | I13: =$E$24*H13*(C13-G13) -> 0 | J13: ='Design Criteria'!$Q$46 -> -5 | K13: =K6 -> 0 | L13: =$E$19*K13*(C13-J13) -> 0 | M13: ='Design Criteria'!$Q$46 -> -5 | N13: =N6 -> 78 | O13: =-$E$21*N13*(M13-C13) -> 755.6049 | P13: ='Design Criteria'!$Q$46 -> -5 | Q13: =Q6 -> 20 | R13: =$E$23*Q13*(-P13+C13) -> 1350 | S13: =S6 -> 0 | T13: =T6 -> 0 | U13: =-$E$20*T13*(S13-C13) -> 0 | V13: 0 | W13: 0 | X13: 0 | Y13: =Y6 -> 1 | Z13: =(F13+I13+O13+R13+U13+L13+V13+W13+X13)*Y13/1000 -> 2.876002 | AA13: =(Z13)/'Design Criteria'!$L$31*1000 -> 3.7374945
D16: sovradimensionamento | E16: 0.25
D17: calc | E17: scelto
A18: U pavimento (W/m2 K) | D18: =SUM(F28:F31)^-1 -> 0.22526231 | E18: =D18*(1+$E$16) -> 0.28157789
A19: U copertura (W/m2 K) | D19: =SUM(F34:F37)^-1 -> 0.33737879 | E19: =D19*(1+$E$16) -> 0.42172349
A20: U parete interna (W/m2 K) | D20: =SUM(F40:F42)^-1 -> 0.28181818 | E20: =D20*(1+$E$16) -> 0.35227273
A21: U parete esterna 1 (W/m2 K) | D21: =SUM(F45:F47)^-1 -> 0.2870294 | E21: =D21*(1+$E$16) -> 0.35878675
A22: U parete esterna 2 (W/m2 K) | D22: =SUM(F50:F52)^-1 -> 0.19415099 | E22: =D22*(1+$E$16) -> 0.24268874
A23: U vetrata esterna (W/m2 K) | D23: 2 | E23: =D23*(1+$E$16) -> 2.5
A24: Solaio interpiano (W/m2 K) | D24: =SUM(F55:F58)^-1 -> 0.61661697 | E24: =D24*(1+$E$16) -> 0.77077121
A25: Controsoffitto (W/m2 K) | D25: =SUM(F61:F63)^-1 -> 2.0911243 | E25: =D25*(1+$E$16) -> 2.6139053
A27: Stratigrafia pavimento contro terra | C27: W/mK | D27: mm | E27: W/m2K | F27: m2K/W | H27: kg/m3 | I27: kg/m2
A28: ai | E28: 9.3 | F28: =1/E28 -> 0.10752688
A29: PVC | C29: 0.2 | D29: 3 | E29: =C29/(D29/1000) -> 66.666667 | F29: =1/E29 -> 0.015 | I29: 20
A30: Calcestruzzo armato | C30: 0.85 | D30: 400 | E30: =C30/(D30/1000) -> 2.125 | F30: =1/E30 -> 0.47058824 | H30: 2400 | I30: =H30*D30/1000 -> 960
A31: Aria | C31: 0.026 | D31: 100 | E31: =C31/(D31/1000) -> 0.26 | F31: =1/E31 -> 3.8461538
A33: Stratigrafia copertura
A34: ae | E34: 23.2 | F34: =1/E34 -> 0.043103448
A35: Massetto - Calcestruzzo | C35: 1.1 | D35: 200 | E35: =C35/(D35/1000) -> 5.5 | F35: =1/E35 -> 0.18181818 | H35: 2400 | I35: =H35*D35/1000 -> 480
A36: Pannello isolante in lana minerale | C36: 0.038 | D36: 100 | E36: =C36/(D36/1000) -> 0.38 | F36: =1/E36 -> 2.6315789 | H36: 150 | I36: =H36*D36/1000 -> 15
A37: ai | E37: 9.3 | F37: =1/E37 -> 0.10752688
I38: =SUM(I34:I37) -> 495
A39: Stratigrafia parete interna
A40: ai | E40: 9.3 | F40: =1/E40 -> 0.10752688
A41: Pannello coibentato | C41: 0.045 | D41: 150 | E41: =C41/(D41/1000) -> 0.3 | F41: =1/E41 -> 3.3333333 | H41: 135 | I41: =H41*D41/1000 -> 20.25
A42: ai | E42: 9.3 | F42: =1/E42 -> 0.10752688
I43: =SUM(I40:I42) -> 20.25
A44: Stratigrafia parete esterna 1
A45: ae | E45: 23.2 | F45: =1/E45 -> 0.043103448
A46: Pannello calcestruzzo prefabbricato | C46: 0.06 | D46: 200 | E46: =C46/(D46/1000) -> 0.3 | F46: =1/E46 -> 3.3333333 | H46: 1000 | I46: =H46*D46/1000 -> 200
A47: ai | E47: 9.3 | F47: =1/E47 -> 0.10752688
...

Sheet Carichi t. LBW(NO PLOT)
A1: Locale | C1: ESTATE
C2: Ti (°C) | D2: Pavimento contro terra | G2: Solaio interpiano con locali non condizionati | J2: Copertura | M2: Pareti Esterne | P2: Vetrate Esterne | S2: Pareti su locali non condizionati | V2: Contrib. irragg.copertura | W2: Irragg. sup vetrate | X2: Contrib. irragg.pareti | Y2: Fatt correttivo altezza | Z2: Q TOT (kW)
A3: Descrizione | B3: Codice | D3: T (°C) | E3: Superficie (m2) | F3: Q (W) | G3: T (°C) | H3: Superficie (m2) | I3: Q (W) | J3: T (°C) | K3: Superficie (m2) | L3: Q (W) | M3: T (°C) | N3: Superficie (m2) | O3: Q (W) | P3: T (°C) | Q3: Superficie (m2) | R3: Q (W) | S3: T (°C) | T3: Superficie (m2) | U3: Q (W) | V3: Q (W) | W3: Q (W) | X3: Q (W) | AA3: W/mc
A4: ='Design Criteria'!D10 -> ENTRANCE | B4: ='Design Criteria'!C10 -> A001 | C4: ='Design Criteria'!M10 -> 22 | D4: 15 | E4: ='Design Criteria'!J10 -> 18.51 | F4: 0 | G4: 30 | H4: 0 | I4: =$E$31*H4*(-C4+G4) -> 0 | J4: ='Design Criteria'!$M$46 -> 36 | K4: 0 | L4: =$E$27*K4*(-C4+J4) -> 0 | M4: ='Design Criteria'!$M$46 -> 36 | N4: =(1.5)*5.5 -> 8.25 | O4: =$E$29*N4*(M4-C4) -> 28.03055 | P4: ='Design Criteria'!$M$46 -> 36 | Q4: 0 | R4: =$E$30*Q4*(P4-C4) -> 0 | S4: 5 | T4: =(11.5)*4.8 -> 55.2 | U4: 0 | V4: =MAX(SUM(P85)-L4,0) -> 0 | W4: =SUM(M69:M69) -> 35.646631 | X4: =MAX(SUM(P86:P89)-O4,0) -> 11.21222 | Y4: 1 | Z4: =(F4+I4+O4+R4+U4+L4+V4+W4+X4)*Y4/1000 -> 0.0748894 | AA4: =(Z4)/'Design Criteria'!$L$10*1000 -> 0.77805553
A5: ='Design Criteria'!D11 -> HANDLING AREA | B5: ='Design Criteria'!C11 -> A002 | C5: ='Design Criteria'!M11 -> 22 | D5: 15 | E5: ='Design Criteria'!J11 -> 366.14 | F5: 0 | G5: 30 | H5: =E5 -> 366.14 | I5: =$E$31*H5*(-C5+G5) -> 2257.6814 | J5: ='Design Criteria'!$M$46 -> 36 | K5: 0 | L5: =$E$27*K5*(-C5+J5) -> 0 | M5: ='Design Criteria'!$M$46 -> 36 | N5: =(23)*5.5+(3.5+6)*5.5+(3.5)*5.5 -> 198 | O5: =$E$29*N5*(M5-C5) -> 672.7332 | P5: ='Design Criteria'!$M$46 -> 36 | Q5: =2.5*1.5+3.5*1.5+1.2*1.2 -> 10.44 | R5: =$E$30*Q5*(P5-C5) -> 365.4 | S5: 5 | T5: =(8.1+6.5)*4.8+(4.5)*4.8 -> 91.68 | U5: 0 | V5: =MAX(SUM(P77)-L5,0) -> 0 | W5: =SUM(M68:M69) -> 1655.948 | X5: =MAX(SUM(P78:P81)-O5,0) -> 343.57445 | Y5: 1 | Z5: =(F5+I5+O5+R5+U5+L5+V5+W5+X5)*Y5/1000 -> 5.295337 | AA5: =(Z5)/'Design Criteria'!$L$11*1000 -> 2.7812696
A6: ='Design Criteria'!D13 -> AIRLOCK VT | B6: ='Design Criteria'!C13 -> A102 | C6: ='Design Criteria'!M13 -> 22 | D6: 15 | E6: 0 | F6: 0 | G6: 30 | H6: ='Design Criteria'!J13 -> 5.9 | I6: =$E$32*H6*(-C6+G6) -> 123.37633 | J6: ='Design Criteria'!$M$46 -> 36 | K6: 0 | L6: =$E$27*K6*(-C6+J6) -> 0 | M6: ='Design Criteria'!$M$46 -> 36 | N6: =(2.8)*2.7 -> 7.56 | O6: =$E$29*N6*(M6-C6) -> 25.686177 | P6: ='Design Criteria'!$M$46 -> 36 | Q6: 0 | R6: =$E$30*Q6*(P6-C6) -> 0 | S6: 30 | T6: =2.2*2.7 -> 5.94 | U6: =$E$28*T6*(S6-C6) -> 16.74 | V6: =MAX(SUM(P93)-L6,0) -> 0 | W6: =SUM(M70:M70) -> 0 | X6: =MAX(SUM(P94:P97)-O6,0) -> 10.274471 | Y6: 1 | Z6: =(F6+I6+O6+R6+U6+L6+V6+W6+X6)*Y6/1000 -> 0.17607698 | AA6: =(Z6)/'Design Criteria'!$L$13*1000 -> 11.053169
A7: ='Design Criteria'!D14 -> CORRIDOR | B7: ='Design Criteria'!C14 -> A103 | C7: ='Design Criteria'!M14 -> 22 | D7: 15 | E7: 0 | F7: 0 | G7: 30 | H7: ='Design Criteria'!J14 -> 23.36 | I7: =$E$32*H7*(-C7+G7) -> 488.48663 | J7: ='Design Criteria'!$M$46 -> 36 | K7: 0 | L7: =$E$27*K7*(-C7+J7) -> 0 | M7: ='Design Criteria'!$M$46 -> 36 | N7: =(1.5)*2.7 -> 4.05 | O7: =$E$29*N7*(M7-C7) -> 13.760452 | P7: ='Design Criteria'!$M$46 -> 36 | Q7: =1.2*1.2 -> 1.44 | R7: =$E$30*Q7*(P7-C7) -> 50.4 | S7: 30 | T7: =1.5*2.7 -> 4.05 | U7: =$E$28*T7*(S7-C7) -> 11.413636 | V7: =MAX(SUM(P101)-L7,0) -> 0 | W7: =SUM(M71:M71) -> 259.24822 | X7: =MAX(SUM(P102:P105)-O7,0) -> 5.5041807 | Y7: 1 | Z7: =(F7+I7+O7+R7+U7+L7+V7+W7+X7)*Y7/1000 -> 0.82881312 | AA7: =(Z7)/'Design Criteria'!$L$14*1000 -> 13.140746
A8: ='Design Criteria'!D22 -> FEMALE WC | B8: ='Design Criteria'!C22 -> A106 | C8: ='Design Criteria'!M22 -> 22 | D8: 15 | E8: 0 | F8: 0 | G8: 30 | H8: ='Design Criteria'!J22 -> 23 | I8: =$E$32*H8*(-C8+G8) -> 480.95858 | J8: ='Design Criteria'!$M$46 -> 36 | K8: 0 | L8: =$E$27*K8*(-C8+J8) -> 0 | M8: ='Design Criteria'!$M$46 -> 36 | N8: 0 | O8: =$E$29*N8*(M8-C8) -> 0 | P8: ='Design Criteria'!$M$46 -> 36 | Q8: 0 | R8: =$E$30*Q8*(P8-C8) -> 0 | S8: 30 | T8: =(3.2)*2.7 -> 8.64 | U8: =$E$28*T8*(S8-C8) -> 24.349091 | V8: 0 | W8: 0 | X8: 0 | Y8: 1 | Z8: =(F8+I8+O8+R8+U8+L8+V8+W8+X8)*Y8/1000 -> 0.50530767 | AA8: =(Z8)/'Design Criteria'!$L$22*1000 -> 8.1369995
A9: ='Design Criteria'!D23 -> FEMALE CHANGING ROOM | B9: ='Design Criteria'!C23 -> A107 | C9: ='Design Criteria'!M23 -> 22 | D9: 15 | E9: 0 | F9: 0 | G9: 30 | H9: ='Design Criteria'!J23 -> 26 | I9: =$E$32*H9*(-C9+G9) -> 543.69231 | J9: ='Design Criteria'!$M$46 -> 36 | K9: 0 | L9: =$E$27*K9*(-C9+J9) -> 0 | M9: ='Design Criteria'!$M$46 -> 36 | N9: 0 | O9: =$E$29*N9*(M9-C9) -> 0 | P9: ='Design Criteria'!$M$46 -> 36 | Q9: 0 | R9: =$E$30*Q9*(P9-C9) -> 0 | S9: 30 | T9: =(3.8)*2.7 -> 10.26 | U9: =$E$28*T9*(S9-C9) -> 28.914545 | V9: 0 | W9: 0 | X9: 0 | Y9: 1 | Z9: =(F9+I9+O9+R9+U9+L9+V9+W9+X9)*Y9/1000 -> 0.57260685 | AA9: =(Z9)/'Design Criteria'!$L$23*1000 -> 8.1567928
A11: ='Design Criteria'!D38 -> ELECTRIC ROOM | B11: ='Design Criteria'!C38 -> E102 | C11: ='Design Criteria'!M38 -> 22 | D11: 15 | E11: 0 | F11: 0 | G11: 30 | H11: 0 | I11: =$E$32*H11*(-C11+G11) -> 0 | J11: ='Design Criteria'!$M$46 -> 36 | K11: ='Design Criteria'!J38 -> 27 | L11: =$E$27*K11*(-C11+J11) -> 159.41148 | M11: ='Design Criteria'!$M$46 -> 36 | N11: 0 | O11: =$E$29*N11*(M11-C11) -> 0 | P11: ='Design Criteria'!$M$46 -> 36 | Q11: 0 | R11: =$E$30*Q11*(P11-C11) -> 0 | S11: 30 | T11: =(13)*4.9 -> 63.7 | U11: =$E$28*T11*(S11-C11) -> 179.51818 | V11: =MAX(SUM(P111)-L11,0) -> 183.3232 | W11: 0 | X11: =MAX(SUM(P112:P115)-O11,0) -> 0 | Y11: 1 | Z11: =(F11+I11+O11+R11+U11+L11+V11+W11+X11)*Y11/1000 -> 0.52225286 | AA11: =(Z11)/(K11*4.9)*1000 -> 3.9474895
A12: Locale | C12: INVERNO
C13: Ti (°C) | D13: Pavimento contro terra | G13: Solaio interpiano | J13: Copertura | M13: Pareti Esterne | P13: Vetrate Esterne | S13: Pareti su locali non condizionati | V13: Contrib. irragg.copertura | W13: Irragg. sup vetrate | X13: Contrib. irragg.pareti | Y13: Fatt correttivo altezza | Z13: Q TOT (kW) | AB13: Q TOT con aria da magazzino refrigerato(kW)
A14: Descrizione | B14: Codice | D14: T (°C) | E14: Superficie (m2) | F14: Q (W) | G14: T (°C) | H14: Superficie (m2) | I14: Q (W) | J14: T (°C) | K14: Superficie (m2) | L14: Q (W) | M14: T (°C) | N14: Superficie (m2) | O14: Q (W) | P14: T (°C) | Q14: Superficie (m2) | R14: Q (W) | S14: T (°C) | T14: Superficie (m2) | U14: Q (W) | V14: Q (W) | W14: Q (W) | X14: Q (W) | AA14: W/mc | AC14: W/mc
A15: =A4 -> ENTRANCE | B15: =B4 -> A001 | C15: ='Design Criteria'!Q10 -> 22 | D15: 10 | E15: =E4 -> 18.51 | F15: =-$E$26*E15*(D15-C15) -> 82.244234 | G15: 10 | H15: =H4 -> 0 | I15: =$E$31*H15*(C15-G15) -> 0 | J15: ='Design Criteria'!$Q$46 -> -5 | K15: =K4 -> 0 | L15: =$E$27*K15*(C15-J15) -> 0 | M15: ='Design Criteria'!$Q$46 -> -5 | N15: =N4 -> 8.25 | O15: =-$E$29*N15*(M15-C15) -> 54.058917 | P15: ='Design Criteria'!$Q$46 -> -5 | Q15: =Q4 -> 0 | R15: =$E$30*Q15*(-P15+C15) -> 0 | S15: =S4 -> 5 | T15: =T4 -> 55.2 | U15: =-$E$28*T15*(S15-C15) -> 330.57273 | V15: 0 | W15: 0 | X15: 0 | Y15: 1.21 | Z15: =(F15+I15+O15+R15+U15+L15+V15+W15+X15)*Y15/1000 -> 0.56491981 | AA15: =(Z15)/'Design Criteria'!$L$10*1000 -> 5.8691748 | AB15: =Z15 -> 0.56491981 | AC15: =(AB15)/'Design Criteria'!$L$10*1000 -> 5.8691748
A16: =A5 -> HANDLING AREA | B16: =B5 -> A002 | C16: ='Design Criteria'!Q11 -> 22 | D16: 10 | E16: =E5 -> 366.14 | F16: =-$E$26*E16*(D16-C16) -> 1626.8452 | G16: 10 | H16: =H5 -> 366.14 | I16: =$E$31*H16*(C16-G16) -> 3386.522 | J16: ='Design Criteria'!$Q$46 -> -5 | K16: =K5 -> 0 | L16: =$E$27*K16*(C16-J16) -> 0 | M16: ='Design Criteria'!$Q$46 -> -5 | N16: =N5 -> 198 | O16: =-$E$29*N16*(M16-C16) -> 1297.414 | P16: ='Design Criteria'!$Q$46 -> -5 | Q16: =Q5 -> 10.44 | R16: =$E$30*Q16*(-P16+C16) -> 704.7 | S16: =S5 -> 5 | T16: =T5 -> 91.68 | U16: =-$E$28*T16*(S16-C16) -> 549.03818 | V16: 0 | W16: 0 | X16: 0 | Y16: 1.21 | Z16: =(F16+I16+O16+R16+U16+L16+V16+W16+X16)*Y16/1000 -> 9.1530685 | AA16: =(Z16)/'Design Criteria'!$L$11*1000 -> 4.8074657 | AB16: =Z16+B125/1000 -> 12.355394 | AC16: =(AB16)/'Design Criteria'!$L$11*1000 -> 6.4894229
A17: =A6 -> AIRLOCK VT | B17: =B6 -> A102 | C17: ='Design Criteria'!Q13 -> 22 | D17: 10 | E17: =E6 -> 0 | F17: =-$E$26*E17*(D17-C17) -> 0 | G17: 10 | H17: =H6 -> 5.9 | I17: =$E$32*H17*(C17-G17) -> 185.0645 | J17: ='Design Criteria'!$Q$46 -> -5 | K17: =K6 -> 0 | L17: =$E$27*K17*(C17-J17) -> 0 | M17: ='Design Criteria'!$Q$46 -> -5 | N17: =N6 -> 7.56 | O17: =-$E$29*N17*(M17-C17) -> 49.537626 | P17: ='Design Criteria'!$Q$46 -> -5 | Q17: =Q6 -> 0 | R17: =$E$30*Q17*(-P17+C17) -> 0 | S17: 10 | T17: =T6 -> 5.94 | U17: =-$E$28*T17*(S17-C17) -> 25.11 | V17: 0 | W17: 0 | X17: 0 | Y17: 1 | Z17: =(F17+I17+O17+R17+U17+L17+V17+W17+X17)*Y17/1000 -> 0.25971212 | AA17: =(Z17)/'Design Criteria'!$L$13*1000 -> 16.303335 | AB17: =Z17 -> 0.25971212 | AC17: =(AB17)/'Design Criteria'!$L$13*1000 -> 16.303335
A18: =A7 -> CORRIDOR | B18: =B7 -> A103 | C18: ='Design Criteria'!Q14 -> 22 | D18: 10 | E18: =E7 -> 0 | F18: =-$E$26*E18*(D18-C18) -> 0 | G18: 10 | H18: =H7 -> 23.36 | I18: =$E$32*H18*(C18-G18) -> 732.72994 | J18: ='Design Criteria'!$Q$46 -> -5 | K18: =K7 -> 0 | L18: =$E$27*K18*(C18-J18) -> 0 | M18: ='Design Criteria'!$Q$46 -> -5 | N18: =N7 -> 4.05 | O18: =-$E$29*N18*(M18-C18) -> 26.538014 | P18: ='Design Criteria'!$Q$46 -> -5 | Q18: =Q7 -> 1.44 | R18: =$E$30*Q18*(-P18+C18) -> 97.2 | S18: 10 | T18: =T7 -> 4.05 | U18: =-$E$28*T18*(S18-C18) -> 17.120455 | V18: 0 | W18: 0 | X18: 0 | Y18: 1 | Z18: =(F18+I18+O18+R18+U18+L18+V18+W18+X18)*Y18/1000 -> 0.87358841 | AA18: =(Z18)/'Design Criteria'!$L$14*1000 -> 13.850653 | AB18: =Z18 -> 0.87358841 | AC18: =(AB18)/'Design Criteria'!$L$14*1000 -> 13.850653
A19: =A8 -> FEMALE WC | B19: =B8 -> A106 | C19: ='Design Criteria'!Q22 -> 22 | D19: 10 | E19: =E8 -> 0 | F19: =-$E$26*E19*(D19-C19) -> 0 | G19: 10 | H19: =H8 -> 23 | I19: =$E$32*H19*(C19-G19) -> 721.43787 | J19: ='Design Criteria'!$Q$46 -> -5 | K19: =K8 -> 0 | L19: =$E$27*K19*(C19-J19) -> 0 | M19: ='Design Criteria'!$Q$46 -> -5 | N19: =N8 -> 0 | O19: =-$E$29*N19*(M19-C19) -> 0 | P19: ='Design Criteria'!$Q$46 -> -5 | Q19: =Q8 -> 0 | R19: =$E$30*Q19*(-P19+C19) -> 0 | S19: 10 | T19: =T8 -> 8.64 | U19: =-$E$28*T19*(S19-C19) -> 36.523636 | V19: 0 | W19: 0 | X19: 0 | Y19: 1 | Z19: =(F19+I19+O19+R19+U19+L19+V19+W19+X19)*Y19/1000 -> 0.75796151 | AA19: =(Z19)/'Design Criteria'!$L$22*1000 -> 12.205499 | AB19: =Z19 -> 0.75796151 | AC19: =(AB19)/'Design Criteria'!$L$22*1000 -> 12.205499
A20: =A9 -> FEMALE CHANGING ROOM | B20: =B9 -> A107 | C20: ='Design Criteria'!Q23 -> 22 | D20: 10 | E20: =E9 -> 0 | F20: =-$E$26*E20*(D20-C20) -> 0 | G20: 10 | H20: =H9 -> 26 | I20: =$E$32*H20*(C20-G20) -> 815.53846 | J20: ='Design Criteria'!$Q$46 -> -5 | K20: =K9 -> 0 | L20: =$E$27*K20*(C20-J20) -> 0 | M20: ='Design Criteria'!$Q$46 -> -5 | N20: =N9 -> 0 | O20: =-$E$29*N20*(M20-C20) -> 0 | P20: ='Design Criteria'!$Q$46 -> -5 | Q20: =Q9 -> 0 | R20: =$E$30*Q20*(-P20+C20) -> 0 | S20: 10 | T20: =T9 -> 10.26 | U20: =-$E$28*T20*(S20-C20) -> 43.371818 | V20: 0 | W20: 0 | X20: 0 | Y20: 1 | Z20: =(F20+I20+O20+R20+U20+L20+V20+W20+X20)*Y20/1000 -> 0.85891028 | AA20: =(Z20)/'Design Criteria'!$L$23*1000 -> 12.235189 | AB20: =Z20 -> 0.85891028 | AC20: =(AB20)/'Design Criteria'!$L$23*1000 -> 12.235189
A22: =A11 -> ELECTRIC ROOM | B22: =B11 -> E102 | C22: ='Design Criteria'!Q38 -> 22 | D22: 10 | E22: =E11 -> 0 | F22: =-$E$26*E22*(D22-C22) -> 0 | G22: 10 | H22: =H11 -> 0 | I22: =$E$32*H22*(C22-G22) -> 0 | J22: ='Design Criteria'!$Q$46 -> -5 | K22: =K11 -> 27 | L22: =$E$27*K22*(C22-J22) -> 307.43642 | M22: ='Design Criteria'!$Q$46 -> -5 | N22: =N11 -> 0 | O22: =-$E$29*N22*(M22-C22) -> 0 | P22: ='Design Criteria'!$Q$46 -> -5 | Q22: =Q11 -> 0 | R22: =$E$30*Q22*(-P22+C22) -> 0 | S22: 10 | T22: =T11 -> 63.7 | U22: =-$E$28*T22*(S22-C22) -> 269.27727 | V22: 0 | W22: 0 | X22: 0 | Y22: 1.21 | Z22: =(F22+I22+O22+R22+U22+L22+V22+W22+X22)*Y22/1000 -> 0.69782357 | AA22: =(Z22)/(K22*4.9)*1000 -> 5.2745546 | AB22: =Z22 -> 0.69782357 | AC22: =AA22 -> 5.2745546
D24: sovradimensionamento | E24: 0.25
D25: calc | E25: scelto
A26: U pavimento (W/m2 K) | D26: =SUM(F35:F38)^-1 -> 0.2962155 | E26: =D26*(1+$E$24) -> 0.37026938
A27: U copertura (W/m2 K) | D27: =SUM(F41:F44)^-1 -> 0.33737879 | E27: =D27*(1+$E$24) -> 0.42172349
A28: U parete interna (W/m2 K) | D28: =SUM(F47:F49)^-1 -> 0.28181818 | E28: =D28*(1+$E$24) -> 0.35227273
A29: U parete esterna (W/m2 K) | D29: =SUM(F52:F54)^-1 -> 0.19415099 | E29: =D29*(1+$E$24) -> 0.24268874
A30: U vetrata esterna (W/m2 K) | D30: 2 | E30: =D30*(1+$E$24) -> 2.5
A31: Solaio interpiano (W/m2 K) | D31: =SUM(F57:F60)^-1 -> 0.61661697 | E31: =D31*(1+$E$24) -> 0.77077121
A32: Controsoffitto (W/m2 K) | D32: =SUM(F63:F65)^-1 -> 2.0911243 | E32: =D32*(1+$E$24) -> 2.6139053
A34: Stratigrafia pavimento contro terra | C34: W/mK | D34: mm | E34: W/m2K | F34: m2K/W | H34: kg/m3 | I34: kg/m2
A35: ai | E35: 9.3 | F35: =1/E35 -> 0.10752688
A36: PVC | C36: 0.2 | D36: 3 | E36: =C36/(D36/1000) -> 66.666667 | F36: =1/E36 -> 0.015 | I36: 20
A37: Calcestruzzo armato | C37: 0.85 | D37: 150 | E37: =C37/(D37/1000) -> 5.6666667 | F37: =1/E37 -> 0.17647059 | H37: 2400 | I37: =H37*D37/1000 -> 360
A38: Aria | C38: 0.026 | D38: 80 | E38: =C38/(D38/1000) -> 0.325 | F38: =1/E38 -> 3.0769231
A40: Stratigrafia copertura
A41: ae | E41: 23.2 | F41: =1/E41 -> 0.043103448
A42: Massetto - Calcestruzzo | C42: 1.1 | D42: 200 | E42: =C42/(D42/1000) -> 5.5 | F42: =1/E42 -> 0.18181818 | H42: 2400 | I42: =H42*D42/1000 -> 480
A43: Pannello isolante in lana minerale | C43: 0.038 | D43: 100 | E43: =C43/(D43/1000) -> 0.38 | F43: =1/E43 -> 2.6315789 | H43: 150 | I43: =H43*D43/1000 -> 15
A44: ai | E44: 9.3 | F44: =1/E44 -> 0.10752688
I45: =SUM(I41:I44) -> 495
...

Sheet Carichi t. LINK(NO PLOT)
A1: Locale | C1: ESTATE
C2: Ti (°C) | D2: Pavimento contro terra | G2: Solaio interpiano con locali non condizionati | J2: Copertura | M2: Pareti Esterne | P2: Vetrate Esterne | S2: Pareti su locali non condizionati | V2: Contrib. irragg.copertura | W2: Irragg. sup vetrate | X2: Contrib. irragg.pareti | Y2: Fatt correttivo altezza | Z2: Q TOT (kW)
A3: Descrizione | B3: Codice | D3: T (°C) | E3: Superficie (m2) | F3: Q (W) | G3: T (°C) | H3: Superficie (m2) | I3: Q (W) | J3: T (°C) | K3: Superficie (m2) | L3: Q (W) | M3: T (°C) | N3: Superficie (m2) | O3: Q (W) | P3: T (°C) | Q3: Superficie (m2) | R3: Q (W) | S3: T (°C) | T3: Superficie (m2) | U3: Q (W) | V3: Q (W) | W3: Q (W) | X3: Q (W) | AA3: W/mc
A4: ='Design Criteria'!D8 -> MATERIAL RECEIVING LINK CORRIDOR | B4: ='Design Criteria'!C8 -> E001 | C4: ='Design Criteria'!M8 -> 22 | D4: 15 | E4: ='Design Criteria'!J8 -> 238.5 | F4: 0 | G4: 30 | H4: 140 | I4: =$E$17*H4*(-C4+G4) -> 355.6062 | J4: ='Design Criteria'!$M$46 -> 36 | K4: =E4-H4 -> 98.5 | L4: =$E$13*K4*(-C4+J4) -> 445.12407 | M4: ='Design Criteria'!$M$46 -> 36 | N4: =(18.7+3.4+11.6+4.6+4.4+36.7)*3.5 -> 277.9 | O4: =$E$15*N4*(M4-C4) -> 944.20482 | P4: NA | Q4: 0 | R4: 0 | S4: 5 | T4: =7.5*3.5 -> 26.25 | U4: 0 | V4: =MAX(SUM(P60)-L4,0) -> 511.89268 | W4: 0 | X4: =MAX(SUM(P61:P64)-O4,0) -> 369.45114 | Y4: 1 | Z4: =(F4+I4+O4+R4+U4+L4+V4+W4+X4)*Y4/1000 -> 2.6262789 | AA4: =(Z4)/'Design Criteria'!$L$8*1000 -> 4.0783895
A5: Locale | C5: INVERNO
C6: Ti (°C) | D6: Pavimento contro terra | G6: Solaio interpiano | J6: Copertura | M6: Pareti Esterne | P6: Vetrate Esterne | S6: Pareti su locali non condizionati | V6: Contrib. irragg.copertura | W6: Irragg. sup vetrate | X6: Contrib. irragg.pareti | Y6: Fatt correttivo altezza | Z6: Q TOT (kW) | AB6: Q TOT con aria da magazzino refrigerato(kW)
A7: Descrizione | B7: Codice | D7: T (°C) | E7: Superficie (m2) | F7: Q (W) | G7: T (°C) | H7: Superficie (m2) | I7: Q (W) | J7: T (°C) | K7: Superficie (m2) | L7: Q (W) | M7: T (°C) | N7: Superficie (m2) | O7: Q (W) | P7: T (°C) | Q7: Superficie (m2) | R7: Q (W) | S7: T (°C) | T7: Superficie (m2) | U7: Q (W) | V7: Q (W) | W7: Q (W) | X7: Q (W) | AA7: W/mc | AC7: W/mc
A8: =A4 -> MATERIAL RECEIVING LINK CORRIDOR | B8: =B4 -> E001 | C8: ='Design Criteria'!Q8 -> 22 | D8: 10 | E8: =E4 -> 238.5 | F8: =-$E$12*E8*(D8-C8) -> 1024.0248 | G8: 10 | H8: =H4 -> 140 | I8: =$E$17*H8*(C8-G8) -> 533.40929 | J8: ='Design Criteria'!$Q$46 -> -5 | K8: =K4 -> 98.5 | L8: =$E$13*K8*(C8-J8) -> 858.45356 | M8: ='Design Criteria'!$Q$46 -> -5 | N8: =N4 -> 277.9 | O8: =-$E$15*N8*(M8-C8) -> 1820.9664 | P8: NA | Q8: NA | R8: 0 | S8: =S4 -> 5 | T8: =T4 -> 26.25 | U8: =-$E$14*T8*(S8-C8) -> 361.3814 | V8: 0 | W8: 0 | X8: 0 | Y8: =Y4 -> 1 | Z8: =(F8+I8+O8+R8+U8+L8+V8+W8+X8)*Y8/1000 -> 4.5982355 | AA8: =(Z8)/'Design Criteria'!$L$8*1000 -> 7.1406717 | AB8: =Z8+B76/1000 -> 6.7331193 | AC8: =(AB8)/'Design Criteria'!$L$8*1000 -> 10.455966
D10: sovradimensionamento | E10: 0.25
D11: calc | E11: scelto
A12: U pavimento (W/m2 K) | D12: =SUM(F20:F23)^-1 -> 0.28624035 | E12: =D12*(1+$E$10) -> 0.35780043
A13: U copertura (W/m2 K) | D13: =SUM(F26:F29)^-1 -> 0.25823006 | E13: =D13*(1+$E$10) -> 0.32278757
A14: U parete interna (W/m2 K) | D14: =SUM(F32:F36)^-1 -> 0.64785462 | E14: =D14*(1+$E$10) -> 0.80981827
A15: U parete esterna (W/m2 K) | D15: =SUM(F39:F41)^-1 -> 0.19415099 | E15: =D15*(1+$E$10) -> 0.24268874
A16: U vetrata esterna (W/m2 K) | D16: 3.2 | E16: =D16*(1+$E$10) -> 4
A17: Solaio interpiano (W/m2 K) | D17: =SUM(F44:F47)^-1 -> 0.25400443 | E17: =D17*(1+$E$10) -> 0.31750553
A19: Stratigrafia pavimento contro terra | C19: W/mK | D19: mm | E19: W/m2K | F19: m2K/W | H19: kg/m3 | I19: kg/m2
A20: ai | E20: 9.3 | F20: =1/E20 -> 0.10752688
A21: PVC | C21: 0.2 | D21: 3 | E21: =C21/(D21/1000) -> 66.666667 | F21: =1/E21 -> 0.015 | I21: 20
A22: Calcestruzzo armato | C22: 0.85 | D22: 250 | E22: =C22/(D22/1000) -> 3.4 | F22: =1/E22 -> 0.29411765 | H22: 2400 | I22: =H22*D22/1000 -> 600
A23: Aria | C23: 0.026 | D23: 80 | E23: =C23/(D23/1000) -> 0.325 | F23: =1/E23 -> 3.0769231
A25: Stratigrafia copertura
A26: ae | E26: 23.2 | F26: =1/E26 -> 0.043103448
A27: Massetto - Calcestruzzo | C27: 1.1 | D27: 20 | E27: =C27/(D27/1000) -> 55 | F27: =1/E27 -> 0.018181818 | H27: 2400 | I27: =H27*D27/1000 -> 48
A28: Lamiera grecata | D28: 80 | E28: 0.27 | F28: =1/E28 -> 3.7037037 | I28: 8.6
A29: ai | E29: 9.3 | F29: =1/E29 -> 0.10752688
I30: =SUM(I26:I29) -> 56.6
A31: Stratigrafia parete interna
A32: ai | E32: 9.3 | F32: =1/E32 -> 0.10752688
A33: Ignilastra cartongesso antincendio | C33: 0.23 | D33: 25 | E33: =C33/(D33/1000) -> 9.2 | F33: =1/E33 -> 0.10869565 | H33: 840 | I33: =H33*D33/1000 -> 21
A34: Lana di roccia | C34: 0.045 | D34: 50 | E34: =C34/(D34/1000) -> 0.9 | F34: =1/E34 -> 1.1111111 | H34: 75 | I34: =H34*D34/1000 -> 3.75
A35: Ignilastra cartongesso antincendio | C35: 0.23 | D35: 25 | E35: =C35/(D35/1000) -> 9.2 | F35: =1/E35 -> 0.10869565 | H35: 840 | I35: =H35*D35/1000 -> 21
A36: ai | E36: 9.3 | F36: =1/E36 -> 0.10752688
I37: =SUM(I32:I36) -> 45.75
A38: Stratigrafia parete esterna
A39: ae | E39: 23.2 | F39: =1/E39 -> 0.043103448
A40: Pannello coibentato | C40: 0.07 | D40: 350 | E40: =C40/(D40/1000) -> 0.2 | F40: =1/E40 -> 5 | H40: 135 | I40: =H40*D40/1000 -> 47.25
A41: ai | E41: 9.3 | F41: =1/E41 -> 0.10752688
I42: =SUM(I39:I41) -> 47.25
A43: Stratigrafia solaio interpiano
...

Sheet COVER FCH
A24: Committente | F24: Titolo Progetto
A25: AENOVA SRL Stabilimento di Borgo San Michele (LT) | F25: SITE DEVELOPMENT ADVANCED BASIC DESIGN
A29: Titolo Documento | F29: Codice Commessa
A30: HVAC FASCICOLO DEI CALCOLI COLD CHAIN | F30: P5323
F32: Codice Documento
F33: P5323FCH001A
A35: Tabella Revisioni
A36: Revisione | B36: Descrizione: | C36: Emesso per RdO | J36: N° pagine:
A37: A | B37: Stesura: | C37: Ingegno | F37: Data: | G37: 45590 | H37: Firma: | I37: ING | J37: 3
B38: Controllo: | C38: Ingegno | F38: Data: | G38: 45590 | H38: Firma: | I38: ING
B39: Approvazione: | C39: L. Galligani | F39: Data: | G39: 45590 | H39: Firma: | I39: LGA
A40: Revisione | B40: Descrizione: | J40: N° pagine:
A41: B | B41: Stesura: | F41: Data: | H41: Firma:
B42: Controllo: | F42: Data: | H42: Firma:
B43: Approvazione: | F43: Data: | H43: Firma:
A48: Questo documento è proprietà della TECHNICONSULT FIRENZE S.r.l. che tutelerà i suoi diritti a termine di legge - This document is the sole property of TECHNICONSULT FIRENZE S.r.l. who will safeguard its rights according to the previsions of law

Sheet PortateAria
A1: UTA AH-102-01 - Macchina a parziale ricircolo
A2: Locale | B2: Descrizione | C2: Classe | D2: Ricambi aria | E2: Area | F2: Volume | G2: TIE | H2: TII | I2: Tot. Carico Sensibile Estate | J2: Dispersioni di calore Inverno | K2: Pressione Ambiente | L2: Calcolo Portata Aria di Mandata | X2: Estrazioni/Espulsioni | Z2: Estrazioni Regime Attenuato | AA2: Infiltrazioni | AB2: Trafilamenti (o Infiltrazioni da soffitto in locali con P negativa) | AC2: Calcolo Portata Aria di Ripresa | AF2: Note
L4: Estate | O4: Inverno | R4: Portata Aria per Ricambi | S4: Portata Aria Calcolata | T4: Portata Aria Adottata | U4: Portata Aria Sovrad. | V4: Regime Attenuato | W4: Ricambi Calcolati | Y4: Portata Aria Sovrad. | AC4: Portata Aria Calcolata | AD4: Portata Aria Adottata | AE4: Portata Aria Sovrad.
L5: T. Immis. | M5: Minima | N5: Calcolata | O5: T. Immis. | P5: Minima | Q5: Calcolata
D6: Vol/amb/h | E6: m2 | F6: m3 | G6: °C | H6: °C | I6: Watt | J6: Watt | K6: Pa | L6: °C | M6: m3/h | N6: Vol/amb/h | O6: °C | P6: m3/h | Q6: Vol/amb/h | R6: m3/h | S6: m3/h | T6: m3/h | U6: m3/h | V6: m3/h | W6: Vol/amb/h | X6: m3/h | Y6: m3/h | Z6: m3/h | AA6: m3/h | AB6: m3/h | AC6: m3/h | AD6: m3/h | AE6: m3/h | AG6: 0.2
A7: ='Design Criteria'!C8 -> E001 | B7: ='Design Criteria'!D8 -> MATERIAL RECEIVING LINK CORRIDOR | C7: ='Design Criteria'!F8 -> NC | D7: ='Design Criteria'!I8 -> 6 | E7: ='Design Criteria'!J8 -> 238.5 | F7: ='Design Criteria'!L8 -> 643.95 | G7: ='Design Criteria'!M8 -> 22 | H7: ='Design Criteria'!Q8 -> 22 | I7: ='Design Criteria'!AA8 -> 9467.775 | J7: ='Design Criteria'!AB8 -> 6761.475 | K7: 0 | L7: 17 | M7: =PRODUCT(I7,0.86,1/0.3,1/(G7-L7)) -> 5428.191 | N7: =M7/F7 -> 8.4295225 | O7: 25 | P7: =PRODUCT(J7,0.86,1/0.3,1/(O7-H7)) -> 6460.965 | Q7: =P7/F7 -> 10.033333 | R7: =D7*F7 -> 3863.7 | S7: =MAXA(M7,P7) -> 6460.965 | T7: =_xlfn.CEILING.MATH(MAX(R7:S7),10) -> 6470 | U7: =_xlfn.CEILING.MATH(T7*(1+$AG$6),10) -> 7770 | V7: =T7 -> 6470 | W7: =T7/F7 -> 10.047364 | X7: 0 | Y7: =_xlfn.CEILING.MATH(X7*(1+$AG$6),10) -> 0 | Z7: =V7-(T7-X7) -> 0 | AA7: 0 | AB7: 0 | AC7: =SUM(T7,-X7,AA7,-AB7) -> 6470 | AD7: =_xlfn.CEILING.MATH(AC7,10) -> 6470 | AE7: =_xlfn.CEILING.MATH(AD7*(1+$AG$6),10) -> 7770
A8: TOTALE | E8: =SUM(E7:E7) -> 238.5 | F8: =SUM(F7:F7) -> 643.95 | I8: =SUM(I7:I7) -> 9467.775 | J8: =SUM(J7:J7) -> 6761.475 | M8: =SUM(M7:M7) -> 5428.191 | P8: =SUM(P7:P7) -> 6460.965 | R8: =SUM(R7:R7) -> 3863.7 | S8: =SUM(S7:S7) -> 6460.965 | T8: =SUM(T7:T7) -> 6470 | U8: =SUM(U7:U7) -> 7770 | V8: =SUM(V7:V7) -> 6470 | X8: =SUM(X7:X7) -> 0 | Y8: =SUM(Y7:Y7) -> 0 | Z8: =SUM(Z7:Z7) -> 0 | AA8: =SUM(AA7:AA7) -> 0 | AB8: =SUM(AB7:AB7) -> 0 | AC8: =SUM(AC7:AC7) -> 6470 | AD8: =SUM(AD7:AD7) -> 6470 | AE8: =SUM(AE7:AE7) -> 7770
T10: Portata Totale Aria di Mandata | AB10: =_xlfn.CEILING.MATH(T8*(1+$AG$6),100) -> 7800 | AC10: m3/h
T11: Portata Totale Aria di Ripresa | AB11: =_xlfn.CEILING.MATH(AD8*(1+$AG$6),100) -> 7800 | AC11: m3/h | AG11: =(AB11-AB12)/AB10 -> 0.87179487 | AH11: Percentuale ricircolo
T12: Portata Totale Aria Espulsa | AB12: 1000 | AC12: m3/h | AG12: =_xlfn.CEILING.MATH(X8*(1+$AG$6),100) -> 0 | AH12: Estrattori dedicati
T13: Portata Totale Aria Esterna | AB13: =AB10-AB11+AB12 -> 1000 | AC13: m3/h | AG13: =AB13/AB10 -> 0.12820513 | AH13: Percentuale aria rinnovo
A16: UTA AH-103-01 - Macchina a parziale ricircolo
A17: Locale | B17: Descrizione | C17: Classe | D17: Ricambi aria | E17: Area | F17: Volume | G17: TIE | H17: TII | I17: Tot. Carico Sensibile Estate | J17: Dispersioni di calore Inverno | K17: Pressione Ambiente | L17: Calcolo Portata Aria di Mandata | X17: Estrazioni/Espulsioni | Z17: Estrazioni Regime Attenuato | AA17: Infiltrazioni | AB17: Trafilamenti (o Infiltrazioni da soffitto in locali con P negativa) | AC17: Calcolo Portata Aria di Ripresa | AF17: Note
L19: Estate | O19: Inverno | R19: Portata Aria per Ricambi | S19: Portata Aria Calcolata | T19: Portata Aria Adottata | U19: Portata Aria Sovrad. | V19: Regime Attenuato | W19: Ricambi Calcolati | Y19: Portata Aria Sovrad. | AC19: Portata Aria Calcolata | AD19: Portata Aria Adottata | AE19: Portata Aria Sovrad.
L20: T. Immis. | M20: Minima | N20: Calcolata | O20: T. Immis. | P20: Minima | Q20: Calcolata
D21: Vol/amb/h | E21: m2 | F21: m3 | G21: °C | H21: °C | I21: Watt | J21: Watt | K21: Pa | L21: °C | M21: m3/h | N21: Vol/amb/h | O21: °C | P21: m3/h | Q21: Vol/amb/h | R21: m3/h | S21: m3/h | T21: m3/h | U21: m3/h | V21: m3/h | W21: Vol/amb/h | X21: m3/h | Y21: m3/h | Z21: m3/h | AA21: m3/h | AB21: m3/h | AC21: m3/h | AD21: m3/h | AE21: m3/h | AG21: 0.2
A22: ='Design Criteria'!C10 -> A001 | B22: ='Design Criteria'!D10 -> ENTRANCE | C22: ='Design Criteria'!F10 -> NC | D22: ='Design Criteria'!I10 -> 3 | E22: ='Design Criteria'!J10 -> 18.51 | F22: ='Design Criteria'!L10 -> 96.252 | G22: ='Design Criteria'!M10 -> 22 | H22: ='Design Criteria'!Q10 -> 22 | I22: ='Design Criteria'!AA10 -> 466.452 | J22: ='Design Criteria'!AB10 -> 577.512 | K22: 0 | L22: 18 | M22: =PRODUCT(I22,0.86,1/0.3,1/(G22-L22)) -> 334.2906 | N22: =M22/F22 -> 3.4730769 | O22: 25 | P22: =PRODUCT(J22,0.86,1/0.3,1/(O22-H22)) -> 551.8448 | Q22: =P22/F22 -> 5.7333333 | R22: =D22*F22 -> 288.756 | S22: =MAXA(M22,P22) -> 551.8448 | T22: =_xlfn.CEILING.MATH(MAX(R22:S22),10) -> 560 | U22: =_xlfn.CEILING.MATH(T22*(1+$AG$6),10) -> 680 | V22: =T22 -> 560 | W22: =T22/F22 -> 5.8180609 | X22: 0 | Y22: =_xlfn.CEILING.MATH(X22*(1+$AG$6),10) -> 0 | Z22: =V22-(T22-X22) -> 0 | AA22: =-SUM('PerditeAria(NO PLOT)'!F141:F143) -> 0 | AB22: ='PerditeAria(NO PLOT)'!F177 -> 0 | AC22: =SUM(T22,-X22,AA22,-AB22) -> 560 | AD22: =_xlfn.CEILING.MATH(AC22,10) -> 560 | AE22: =_xlfn.CEILING.MATH(AD22*(1+$AG$6),10) -> 680
A23: ='Design Criteria'!C11 -> A002 | B23: ='Design Criteria'!D11 -> HANDLING AREA | C23: ='Design Criteria'!F11 -> NC | D23: ='Design Criteria'!I11 -> 3 | E23: ='Design Criteria'!J11 -> 366.14 | F23: ='Design Criteria'!L11 -> 1903.928 | G23: ='Design Criteria'!M11 -> 22 | H23: ='Design Criteria'!Q11 -> 22 | I23: ='Design Criteria'!AA11 -> 15497.084 | J23: ='Design Criteria'!AB11 -> 12375.532 | K23: 0 | L23: 17 | M23: =PRODUCT(I23,0.86,1/0.3,1/(G23-L23)) -> 8884.9948 | N23: =M23/F23 -> 4.6666654 | O23: 26 | P23: =PRODUCT(J23,0.86,1/0.3,1/(O23-H23)) -> 8869.1313 | Q23: =P23/F23 -> 4.6583333 | R23: =D23*F23 -> 5711.784 | S23: =MAXA(M23,P23) -> 8884.9948 | T23: =_xlfn.CEILING.MATH(MAX(R23:S23),10) -> 8890 | U23: =_xlfn.CEILING.MATH(T23*(1+$AG$6),10) -> 10670 | V23: =T23 -> 8890 | W23: =T23/F23 -> 4.6692942 | X23: 0 | Y23: =_xlfn.CEILING.MATH(X23*(1+$AG$6),10) -> 0 | Z23: =V23-(T23-X23) -> 0 | AA23: =-SUM('PerditeAria(NO PLOT)'!F144:F144) -> 0 | AB23: ='PerditeAria(NO PLOT)'!F178 -> 0 | AC23: =SUM(T23,-X23,AA23,-AB23) -> 8890 | AD23: =_xlfn.CEILING.MATH(AC23,10) -> 8890 | AE23: =_xlfn.CEILING.MATH(AD23*(1+$AG$6),10) -> 10670
A24: ='Design Criteria'!C12 -> A101 | B24: ='Design Criteria'!D12 -> FILTER AGAINST FIRE | C24: ='Design Criteria'!F12 -> NC | D24: ='Design Criteria'!I12 -> 6 | E24: ='Design Criteria'!J12 -> 8.9 | F24: ='Design Criteria'!L12 -> 24.03 | G24: ='Design Criteria'!M12 -> 22 | H24: ='Design Criteria'!Q12 -> 22 | I24: ='Design Criteria'!AA12 -> 454.345 | J24: ='Design Criteria'!AB12 -> 396.495 | K24: 0 | L24: =$L$22 -> 18 | M24: =PRODUCT(I24,0.86,1/0.3,1/(G24-L24)) -> 325.61392 | N24: =M24/F24 -> 13.550309 | O24: =$O$22 -> 25 | P24: =PRODUCT(J24,0.86,1/0.3,1/(O24-H24)) -> 378.873 | Q24: =P24/F24 -> 15.766667 | R24: =D24*F24 -> 144.18 | S24: =MAXA(M24,P24) -> 378.873 | T24: =_xlfn.CEILING.MATH(MAX(R24:S24),10) -> 380 | U24: =_xlfn.CEILING.MATH(T24*(1+$AG$6),10) -> 460 | V24: =T24 -> 380 | W24: =T24/F24 -> 15.813566 | X24: 0 | Y24: =_xlfn.CEILING.MATH(X24*(1+$AG$6),10) -> 0 | Z24: =V24-(T24-X24) -> 0 | AA24: 0 | AB24: 0 | AC24: =SUM(T24,-X24,AA24,-AB24) -> 380 | AD24: =_xlfn.CEILING.MATH(AC24,10) -> 380 | AE24: =_xlfn.CEILING.MATH(AD24*(1+$AG$6),10) -> 460
A25: ='Design Criteria'!C13 -> A102 | B25: ='Design Criteria'!D13 -> AIRLOCK VT | C25: ='Design Criteria'!F13 -> NC | D25: ='Design Criteria'!I13 -> 6 | E25: ='Design Criteria'!J13 -> 5.9 | F25: ='Design Criteria'!L13 -> 15.93 | G25: ='Design Criteria'!M13 -> 22 | H25: ='Design Criteria'!Q13 -> 22 | I25: ='Design Criteria'!AA13 -> 301.195 | J25: ='Design Criteria'!AB13 -> 262.845 | K25: 0 | L25: =$L$22 -> 18 | M25: =PRODUCT(I25,0.86,1/0.3,1/(G25-L25)) -> 215.85642 | N25: =M25/F25 -> 13.550309 | O25: =$O$22 -> 25 | P25: =PRODUCT(J25,0.86,1/0.3,1/(O25-H25)) -> 251.163 | Q25: =P25/F25 -> 15.766667 | R25: =D25*F25 -> 95.58 | S25: =MAXA(M25,P25) -> 251.163 | T25: =_xlfn.CEILING.MATH(MAX(R25:S25),10) -> 260 | U25: =_xlfn.CEILING.MATH(T25*(1+$AG$6),10) -> 320 | V25: =T25 -> 260 | W25: =T25/F25 -> 16.321406 | X25: 0 | Y25: =_xlfn.CEILING.MATH(X25*(1+$AG$6),10) -> 0 | Z25: =V25-(T25-X25) -> 0 | AA25: 0 | AB25: 0 | AC25: =SUM(T25,-X25,AA25,-AB25) -> 260 | AD25: =_xlfn.CEILING.MATH(AC25,10) -> 260 | AE25: =_xlfn.CEILING.MATH(AD25*(1+$AG$6),10) -> 320
A26: ='Design Criteria'!C14 -> A103 | B26: ='Design Criteria'!D14 -> CORRIDOR | C26: ='Design Criteria'!F14 -> NC | D26: ='Design Criteria'!I14 -> 6 | E26: ='Design Criteria'!J14 -> 23.36 | F26: ='Design Criteria'!L14 -> 63.072 | G26: ='Design Criteria'!M14 -> 22 | H26: ='Design Criteria'!Q14 -> 22 | I26: ='Design Criteria'!AA14 -> 1318.672 | J26: ='Design Criteria'!AB14 -> 883.008 | K26: 0 | L26: =$L$22 -> 18 | M26: =PRODUCT(I26,0.86,1/0.3,1/(G26-L26)) -> 945.04827 | N26: =M26/F26 -> 14.983642 | O26: =$O$22 -> 25 | P26: =PRODUCT(J26,0.86,1/0.3,1/(O26-H26)) -> 843.7632 | Q26: =P26/F26 -> 13.377778 | R26: =D26*F26 -> 378.432 | S26: =MAXA(M26,P26) -> 945.04827 | T26: =_xlfn.CEILING.MATH(MAX(R26:S26),10) -> 950 | U26: =_xlfn.CEILING.MATH(T26*(1+$AG$6),10) -> 1140 | V26: =T26 -> 950 | W26: =T26/F26 -> 15.062151 | X26: 0 | Y26: =_xlfn.CEILING.MATH(X26*(1+$AG$6),10) -> 0 | Z26: =V26-(T26-X26) -> 0 | AA26: =-SUM('PerditeAria(NO PLOT)'!F147:F148) -> -140 | AB26: 0 | AC26: =SUM(T26,-X26,AA26,-AB26) -> 810 | AD26: =_xlfn.CEILING.MATH(AC26,10) -> 810 | AE26: =_xlfn.CEILING.MATH(AD26*(1+$AG$6),10) -> 980
